Traceback (most recent call last):
  File "/home/al3x/.cache/pypoetry/virtualenvs/data-projects-tPUdKRYy-py3.12/lib/python3.12/site-packages/jupyter_cache/executors/utils.py", line 58, in single_nb_execution
    executenb(
  File "/home/al3x/.cache/pypoetry/virtualenvs/data-projects-tPUdKRYy-py3.12/lib/python3.12/site-packages/nbclient/client.py", line 1319, in execute
    return NotebookClient(nb=nb, resources=resources, km=km, **kwargs).execute()
           ^^^^^^^^^^^^^^^^^^^^^^^^^^^^^^^^^^^^^^^^^^^^^^^^^^^^^^^^^^^^^^^^^^^^^
  File "/home/al3x/.cache/pypoetry/virtualenvs/data-projects-tPUdKRYy-py3.12/lib/python3.12/site-packages/jupyter_core/utils/__init__.py", line 165, in wrapped
    return loop.run_until_complete(inner)
           ^^^^^^^^^^^^^^^^^^^^^^^^^^^^^^
  File "/home/al3x/.asdf/installs/python/3.12.9/lib/python3.12/asyncio/base_events.py", line 691, in run_until_complete
    return future.result()
           ^^^^^^^^^^^^^^^
  File "/home/al3x/.cache/pypoetry/virtualenvs/data-projects-tPUdKRYy-py3.12/lib/python3.12/site-packages/nbclient/client.py", line 709, in async_execute
    await self.async_execute_cell(
  File "/home/al3x/.cache/pypoetry/virtualenvs/data-projects-tPUdKRYy-py3.12/lib/python3.12/site-packages/nbclient/client.py", line 1062, in async_execute_cell
    await self._check_raise_for_error(cell, cell_index, exec_reply)
  File "/home/al3x/.cache/pypoetry/virtualenvs/data-projects-tPUdKRYy-py3.12/lib/python3.12/site-packages/nbclient/client.py", line 918, in _check_raise_for_error
    raise CellExecutionError.from_cell_and_msg(cell, exec_reply_content)
nbclient.exceptions.CellExecutionError: An error occurred while executing the following cell:
------------------
HEADERS = [
    "species", 
    "latin_species", 
    "family",
    "variety", 
    "origin_canada", 
    "edible"
]

with open('data/species-data.csv', 'w', newline='',encoding='utf-8') as outfile:
    writer = csv.writer(outfile)
    writer.writerow(HEADERS)
    
    for row in data_out:
        writer.writerow(row)
------------------


[31m---------------------------------------------------------------------------[39m
[31mFileNotFoundError[39m                         Traceback (most recent call last)
[36mCell[39m[36m [39m[32mIn[4][39m[32m, line 10[39m
[32m      1[39m HEADERS = [
[32m      2[39m     [33m"[39m[33mspecies[39m[33m"[39m, 
[32m      3[39m     [33m"[39m[33mlatin_species[39m[33m"[39m, 
[32m   (...)[39m[32m      7[39m     [33m"[39m[33medible[39m[33m"[39m
[32m      8[39m ]
[32m---> [39m[32m10[39m [38;5;28;01mwith[39;00m [38;5;28;43mopen[39;49m[43m([49m[33;43m'[39;49m[33;43mdata/species-data.csv[39;49m[33;43m'[39;49m[43m,[49m[43m [49m[33;43m'[39;49m[33;43mw[39;49m[33;43m'[39;49m[43m,[49m[43m [49m[43mnewline[49m[43m=[49m[33;43m'[39;49m[33;43m'[39;49m[43m,[49m[43mencoding[49m[43m=[49m[33;43m'[39;49m[33;43mutf-8[39;49m[33;43m'[39;49m[43m)[49m [38;5;28;01mas[39;00m outfile:
[32m     11[39m     writer = csv.writer(outfile)
[32m     12[39m     writer.writerow(HEADERS)

[36mFile [39m[32m~/.cache/pypoetry/virtualenvs/data-projects-tPUdKRYy-py3.12/lib/python3.12/site-packages/IPython/core/interactiveshell.py:325[39m, in [36m_modified_open[39m[34m(file, *args, **kwargs)[39m
[32m    318[39m [38;5;28;01mif[39;00m file [38;5;129;01min[39;00m {[32m0[39m, [32m1[39m, [32m2[39m}:
[32m    319[39m     [38;5;28;01mraise[39;00m [38;5;167;01mValueError[39;00m(
[32m    320[39m         [33mf[39m[33m"[39m[33mIPython won[39m[33m'[39m[33mt let you open fd=[39m[38;5;132;01m{[39;00mfile[38;5;132;01m}[39;00m[33m by default [39m[33m"[39m
[32m    321[39m         [33m"[39m[33mas it is likely to crash IPython. If you know what you are doing, [39m[33m"[39m
[32m    322[39m         [33m"[39m[33myou can use builtins[39m[33m'[39m[33m open.[39m[33m"[39m
[32m    323[39m     )
[32m--> [39m[32m325[39m [38;5;28;01mreturn[39;00m [43mio_open[49m[43m([49m[43mfile[49m[43m,[49m[43m [49m[43m*[49m[43margs[49m[43m,[49m[43m [49m[43m*[49m[43m*[49m[43mkwargs[49m[43m)[49m

[31mFileNotFoundError[39m: [Errno 2] No such file or directory: 'data/species-data.csv'

